Workbook

Sheet Posts (RAW)
A1: PostID | B1: Platform | C1: Date | D1: ContentType | E1: Hashtags | F1: Likes | G1: Shares | H1: Comments | I1: Clicks | J1: Reach | K1: Impressions | L1: Campaign
A2: A1 | B2: YouTube | C2: 2024-12-23 | D2: Image | E2: #AppleWatchUltra2 #HealthTech | F2: 24516 | G2: 976 | H2: 974 | I2: 2675 | J2: 23275 | K2: 202932 | L2: Apple Watch Ultra 2 Launch
A3: A2 | B3: LinkedIn | C3: 45903 | D3: Image | E3: #MacBookAirM3 #AppleInnovation | F3: 4779 | G3: 1110 | H3: 436 | I3: 1574 | J3: 77167 | K3: 71585 | L3: Apple Event September 2025
A4: A3 | B4: Instagram | C4: 2025-05-12 | D4: Tweet | E4: #AppleDesign #Innovation | F4: 19308 | G4: 1318 | H4: 795 | I4: 1499 | J4: 52307 | K4: 193087 | L4: Sustainability Awareness Drive
A5: A4 | B5: YouTube | C5: 2024-08-12 | D5: Video | E5: #AppleEvent #iPadPro | F5: 3581 | G5: 517 | H5: 880 | I5: 1925 | J5: 18636 | K5: 248611 | L5: iPhone 16 Launch
A6: A5 | B6: YouTube | C6: 45904 | D6: Video | E6: #AppleWatchUltra2 #HealthTech | F6: 21708 | G6: 435 | H6: 317 | I6: 1213 | J6: 70701 | K6: 83585 | L6: Apple Event September 2025
A7: A6 | B7: LinkedIn | C7: 45905 | D7: Image | E7: #ShotOniPhone | F7: 14677 | G7: 533 | H7: 759 | I7: 753 | J7: 23275 | K7: 66958 | L7: Apple Event September 2025
A8: A7 | B8: Instagram | C8: 2024-06-24 | D8: Carousel | E8: #AppleMusic #AppleLifestyle | F8: 7713 | G8: 575 | H8: 417 | I8: 336 | J8: 61660 | K8: 66017 | L8: iPhone 16 Launch
A9: A8 | B9: Instagram | C9: 2024-07-13 | D9: Video | E9: #AppleWatch #Health | F9: 18639 | G9: 1360 | H9: 898 | I9: 2011 | J9: 42841 | K9: 247779 | L9: iPhone 16 Launch
A10: A9 | B10: YouTube | C10: 2024-08-30 | D10: Carousel | E10: #MacBookAirM3 #AppleInnovation | F10: 6804 | G10: 787 | H10: 970 | I10: 1095 | J10: 56343 | K10: 164677 | L10: Apple Watch Ultra 2 Launch
A11: A10 | B11: Twitter | C11: 2025-03-11 | D11: Video | E11: #iPhone16Launch #AppleEvent | F11: 20222 | G11: 712 | H11: 604 | I11: 1272 | J11: 71598 | K11: 216422 | L11: Sustainability Awareness Drive
A12: A11 | B12: YouTube | C12: 2025-02-02 | D12: Carousel | E12: #AppleEvent #iPadPro | F12: 12136 | G12: 1117 | H12: 834 | I12: 892 | J12: 24675 | K12: 183273 | L12: Sustainability Awareness Drive
A13: A12 | B13: YouTube | C13: 2024-07-21 | D13: Tweet | E13: #MacBookAirM3 #AppleInnovation | F13: 2009 | G13: 1072 | H13: 550 | I13: 1437 | J13: 22982 | K13: 69426 | L13: iPhone 16 Launch
A14: A13 | B14: YouTube | C14: 2024-11-18 | D14: Carousel | E14: #AppleMusic #AppleLifestyle | F14: 21255 | G14: 1452 | H14: 625 | I14: 1624 | J14: 21282 | K14: 57778 | L14: MacBook Air M3 Campaign
A15: A14 | B15: YouTube | C15: 45906 | D15: Tweet | E15: #AppleWatch #Health | F15: 7124 | G15: 469 | H15: 851 | I15: 2571 | J15: 33802 | K15: 216313 | L15: Apple Event September 2025
A16: A15 | B16: LinkedIn | C16: 45907 | D16: Tweet | E16: #AppleDesign #Innovation | F16: 3015 | G16: 997 | H16: 783 | I16: 617 | J16: 77167 | K16: 82229 | L16: Apple Event September 2025
A17: A16 | B17: Instagram | C17: 2024-08-26 | D17: Carousel | E17: #AppleWatch #Health | F17: 4193 | G17: 924 | H17: 707 | I17: 2696 | J17: 55075 | K17: 126652 | L17: iPhone 16 Launch
A18: A17 | B18: LinkedIn | C18: 2025-05-05 | D18: Tweet | E18: #AppleEvent #iPhone16 | F18: 10415 | G18: 1388 | H18: 725 | I18: 2462 | J18: 53082 | K18: 168267 | L18: MacBook Air M3 Campaign
A19: A18 | B19: LinkedIn | C19: 2024-08-19 | D19: Image | E19: #AppleWatch #Health | F19: 15550 | G19: 204 | H19: 279 | I19: 1646 | J19: 35819 | K19: 219436 | L19: Apple Watch Ultra 2 Launch
A20: A19 | B20: LinkedIn | C20: 2024-06-23 | D20: Tweet | E20: #AppleEvent #iPhone16 | F20: 16512 | G20: 1050 | H20: 971 | I20: 1891 | J20: 15865 | K20: 166503 | L20: iPhone 16 Launch
A21: A20 | B21: YouTube | C21: 2024-09-09 | D21: Video | E21: #AppleDesign #Innovation | F21: 6158 | G21: 277 | H21: 512 | I21: 2189 | J21: 76881 | K21: 124878 | L21: iPhone 16 Launch
A22: A21 | B22: Twitter | C22: 45908 | D22: Carousel | E22: #iPhonePhotography #ShotOniPhone | F22: 22309 | G22: 773 | H22: 854 | I22: 2387 | J22: 72396 | K22: 97056 | L22: Apple Event September 2025
A23: A22 | B23: Instagram | C23: 2025-02-27 | D23: Image | E23: #AppleMusic #AppleLifestyle | F23: 8970 | G23: 331 | H23: 968 | I23: 2296 | J23: 24613 | K23: 198562 | L23: iPhone 16 Launch
A24: A23 | B24: Twitter | C24: 2024-11-06 | D24: Carousel | E24: #AppleEvent #iPhone16 | F24: 8938 | G24: 800 | H24: 842 | I24: 2072 | J24: 31736 | K24: 59975 | L24: iPhone 16 Launch
A25: A24 | B25: LinkedIn | C25: 2025-01-23 | D25: Video | E25: #iPhone16Launch #AppleEvent | F25: 23168 | G25: 1265 | H25: 441 | I25: 1612 | J25: 66615 | K25: 197795 | L25: iPhone 16 Launch
A26: A25 | B26: LinkedIn | C26: 45909 | D26: Video | E26: #AppleWatch #Health | F26: 15772 | G26: 288 | H26: 520 | I26: 1585 | J26: 59182 | K26: 194351 | L26: Apple Event September 2025
A27: A26 | B27: Twitter | C27: 2025-04-05 | D27: Video | E27: #AppleWatch #Health | F27: 22384 | G27: 601 | H27: 943 | I27: 515 | J27: 41309 | K27: 249373 | L27: Apple Watch Ultra 2 Launch
A28: A27 | B28: Twitter | C28: 2024-09-17 | D28: Tweet | E28: #iPhone16Launch #AppleEvent | F28: 20017 | G28: 495 | H28: 178 | I28: 2683 | J28: 32244 | K28: 182633 | L28: Apple Watch Ultra 2 Launch
A29: A28 | B29: Twitter | C29: 2025-03-04 | D29: Tweet | E29: #ShotOniPhone | F29: 12344 | G29: 815 | H29: 298 | I29: 2439 | J29: 6259 | K29: 237133 | L29: iPhone 16 Launch
A30: A29 | B30: LinkedIn | C30: 45910 | D30: Carousel | E30: #MacBookProM3 | F30: 9266 | G30: 999 | H30: 928 | I30: 2700 | J30: 12264 | K30: 128397 | L30: Apple Event September 2025
A31: A30 | B31: LinkedIn | C31: 2025-02-25 | D31: Carousel | E31: #iPhonePhotography #ShotOniPhone | F31: 10702 | G31: 621 | H31: 445 | I31: 2918 | J31: 54808 | K31: 220225 | L31: Apple Watch Ultra 2 Launch
A32: A31 | B32: Instagram | C32: 2024-12-16 | D32: Image | E32: #AppleEvent #iPadPro | F32: 2384 | G32: 1246 | H32: 160 | I32: 2004 | J32: 2701 | K32: 73142 | L32: Apple Watch Ultra 2 Launch
A33: A32 | B33: Instagram | C33: 2024-07-31 | D33: Image | E33: #AppleEvent #iPhone16 | F33: 2404 | G33: 774 | H33: 661 | I33: 662 | J33: 12676 | K33: 66916 | L33: Apple Watch Ultra 2 Launch
A34: A33 | B34: LinkedIn | C34: 45911 | D34: Carousel | E34: #iPhone16Launch #AppleEvent | F34: 10175 | G34: 342 | H34: 825 | I34: 2904 | J34: 15954 | K34: 104324 | L34: Apple Event September 2025
A35: A34 | B35: Twitter | C35: 45912 | D35: Tweet | E35: #AppleDesign #Innovation | F35: 17158 | G35: 1192 | H35: 262 | I35: 2016 | J35: 28771 | K35: 216037 | L35: Apple Event September 2025
A36: A35 | B36: Twitter | C36: 2024-11-30 | D36: Video | E36: #AppleEvent #iPhone16 | F36: 14763 | G36: 864 | H36: 336 | I36: 1493 | J36: 33310 | K36: 165932 | L36: iPhone 16 Launch
A37: A36 | B37: Instagram | C37: 2025-04-19 | D37: Carousel | E37: #MacBookProM3 | F37: 20384 | G37: 344 | H37: 956 | I37: 655 | J37: 67621 | K37: 175720 | L37: Sustainability Awareness Drive
A38: A37 | B38: LinkedIn | C38: 2025-01-06 | D38: Image | E38: #AppleDesign #Innovation | F38: 11860 | G38: 1448 | H38: 893 | I38: 490 | J38: 23518 | K38: 206205 | L38: Apple Watch Ultra 2 Launch
A39: A38 | B39: Instagram | C39: 2025-02-17 | D39: Tweet | E39: #MacBookAirM3 #AppleInnovation | F39: 7989 | G39: 1206 | H39: 376 | I39: 2769 | J39: 27550 | K39: 221749 | L39: Sustainability Awareness Drive
A40: A39 | B40: Instagram | C40: 45913 | D40: Carousel | E40: #AppleMusic #AppleLifestyle | F40: 17106 | G40: 702 | H40: 459 | I40: 999 | J40: 59627 | K40: 136059 | L40: Apple Event September 2025
...

Sheet Engagement Summary (RAW)
A1: Week_Start_Date | B1: Platform | C1: New_Followers | D1: Unfollows | E1: Total_Followers | F1: Engagement_Rate | G1: Ad_Spend
A2: 2024-06-03 | B2: Instagram | C2: 4138 | D2: 361 | E2: 103777 | F2: 56.637791 | G2: 23944
A3: 2024-06-03 | B3: Twitter | C3: 8693 | D3: 1261 | E3: 111209 | F3: 69.475492 | G3: 29873
A4: 2024-06-03 | B4: YouTube | C4: 9264 | D4: 1141 | E4: 119332 | F4: 92.312205 | G4: 50372
A5: 2024-06-03 | B5: YouTube | C5: 8842 | D5: 971 | E5: 127203 | F5: 16.351816 | G5: 33928
A6: 2024-06-10 | B6: Instagram | C6: 7721 | D6: 506 | E6: 134418 | F6: 35.577824 | G6: 25379
A7: 2024-06-10 | B7: YouTube | C7: 8002 | D7: 524 | E7: 141896 | F7: 52.064893 | G7: 46751
A8: 2024-06-10 | B8: Twitter | C8: 5225 | D8: 291 | E8: 146830 | F8: 19.551863 | G8: 44546
A9: 2024-06-10 | B9: Twitter | C9: 3978 | D9: 543 | E9: 150265 | F9: 49.159818 | G9: 34286
A10: 2024-06-17 | B10: Instagram | C10: 8373 | D10: 921 | E10: 157717 | F10: 12.226329 | G10: 15110
A11: 2024-06-17 | B11: Twitter | C11: 6907 | D11: 834 | E11: 163790 | F11: 54.158984 | G11: 22087
A12: 2024-06-17 | B12: LinkedIn | C12: 7097 | D12: 369 | E12: 170518 | F12: 9.2506363 | G12: 33762
A13: 2024-06-17 | B13: Instagram | C13: 6656 | D13: 978 | E13: 176196 | F13: 60.425889 | G13: 27081
... A201: 2025-05-12 | B201: Twitter | C201: 8527 | D201: 1091 | E201: 1186398 | F201: 1.6760817 | G201: 41703

Sheet Campaign Metadata (RAW)
A1: Campaign_Name | B1: Start_Date | C1: End_Date | D1: Objective | E1: Ad_Spend | F1: Impressions | G1: Engagement_Uplift
A2: iPhone 16 Launch | B2: 2024-06-15 | C2: 2024-07-15 | D2: Product Launch | E2: 85000 | F2: 950000 | G2: 0.45
A3: MacBook Air M3 Campaign | B3: 2024-10-01 | C3: 2024-10-31 | D3: Product Promotion | E3: 60000 | F3: 780000 | G3: 0.38
A4: Apple Watch Ultra 2 Launch | B4: 2024-12-25 | C4: 2025-01-10 | D4: Health & Fitness Awareness | E4: 55000 | F4: 700000 | G4: 0.41
A5: Sustainability Awareness Drive | B5: 2025-03-01 | C5: 2025-03-31 | D5: Sustainability Branding | E5: 40000 | F5: 550000 | G5: 0.32
A6: Apple Event September 2025 | B6: 45901 | C6: 45930 | D6: Brand Engagement | E6: 75000 | F6: 880000 | G6: 0.47

Sheet Posts
A1: PostID | B1: Platform | C1: Date | D1: ContentType | E1: Hashtags.1 | F1: Hashtags.2 | G1: Likes | H1: Shares | I1: Comments | J1: Clicks | K1: Reach | L1: Impressions | M1: Campaign | N1: Engagement Rate | O1: HASTAGS | P1: CLICKS | Q1: Impressions | R1: Engagement Rate
A2: A1 | B2: YouTube | C2: 45649 | D2: Image | E2: #AppleWatchUltra2 | F2: #HealthTech | G2: 24516 | H2: 976 | I2: 974 | J2: 2675 | K2: 23275 | L2: 202932 | M2: Apple Watch Ultra 2 Launch | N2: =(Posts[[#This Row],[Likes]]+Posts[[#This Row],[Shares]]+Posts[[#This Row],[Comments]])/Posts[[#This Row],[Impressions]] -> 0.13041807 | O2: #HealthTech | P2: 2675 | Q2: 202932 | R2: =(Posts[[#This Row],[Likes]]+Posts[[#This Row],[Shares]]+Posts[[#This Row],[Comments]])/Posts[[#This Row],[Impressions]] -> 0.13041807
A3: A2 | B3: LinkedIn | C3: 45903 | D3: Image | E3: #MacBookAirM3 | F3: #AppleInnovation | G3: 4779 | H3: 1110 | I3: 436 | J3: 1574 | K3: 77167 | L3: 71585 | M3: Apple Event September 2025 | N3: =(Posts[[#This Row],[Likes]]+Posts[[#This Row],[Shares]]+Posts[[#This Row],[Comments]])/Posts[[#This Row],[Impressions]] -> 0.088356499 | O3: #AppleInnovation | P3: 1574 | Q3: 71585 | R3: =(Posts[[#This Row],[Likes]]+Posts[[#This Row],[Shares]]+Posts[[#This Row],[Comments]])/Posts[[#This Row],[Impressions]] -> 0.088356499
A4: A3 | B4: Instagram | C4: 45789 | D4: Tweet | E4: #AppleDesign | F4: #Innovation | G4: 19308 | H4: 1318 | I4: 795 | J4: 1499 | K4: 52307 | L4: 193087 | M4: Sustainability Awareness Drive | N4: =(Posts[[#This Row],[Likes]]+Posts[[#This Row],[Shares]]+Posts[[#This Row],[Comments]])/Posts[[#This Row],[Impressions]] -> 0.11093963 | O4: #Innovation | P4: 1499 | Q4: 193087 | R4: =(Posts[[#This Row],[Likes]]+Posts[[#This Row],[Shares]]+Posts[[#This Row],[Comments]])/Posts[[#This Row],[Impressions]] -> 0.11093963
A5: A4 | B5: YouTube | C5: 45516 | D5: Video | E5: #AppleEvent | F5: #iPadPro | G5: 3581 | H5: 517 | I5: 880 | J5: 1925 | K5: 18636 | L5: 248611 | M5: iPhone 16 Launch | N5: =(Posts[[#This Row],[Likes]]+Posts[[#This Row],[Shares]]+Posts[[#This Row],[Comments]])/Posts[[#This Row],[Impressions]] -> 0.020023249 | O5: #iPadPro | P5: 1925 | Q5: 248611 | R5: =(Posts[[#This Row],[Likes]]+Posts[[#This Row],[Shares]]+Posts[[#This Row],[Comments]])/Posts[[#This Row],[Impressions]] -> 0.020023249
A6: A5 | B6: YouTube | C6: 45904 | D6: Video | E6: #AppleWatchUltra2 | F6: #HealthTech | G6: 21708 | H6: 435 | I6: 317 | J6: 1213 | K6: 70701 | L6: 83585 | M6: Apple Event September 2025 | N6: =(Posts[[#This Row],[Likes]]+Posts[[#This Row],[Shares]]+Posts[[#This Row],[Comments]])/Posts[[#This Row],[Impressions]] -> 0.2687085 | O6: #HealthTech | P6: 1213 | Q6: 83585 | R6: =(Posts[[#This Row],[Likes]]+Posts[[#This Row],[Shares]]+Posts[[#This Row],[Comments]])/Posts[[#This Row],[Impressions]] -> 0.2687085
A7: A6 | B7: LinkedIn | C7: 45905 | D7: Image | E7: #ShotOniPhone | F7: NA | G7: 14677 | H7: 533 | I7: 759 | J7: 753 | K7: 23275 | L7: 66958 | M7: Apple Event September 2025 | N7: =(Posts[[#This Row],[Likes]]+Posts[[#This Row],[Shares]]+Posts[[#This Row],[Comments]])/Posts[[#This Row],[Impressions]] -> 0.23849279 | O7: NA | P7: 753 | Q7: 66958 | R7: =(Posts[[#This Row],[Likes]]+Posts[[#This Row],[Shares]]+Posts[[#This Row],[Comments]])/Posts[[#This Row],[Impressions]] -> 0.23849279
A8: A7 | B8: Instagram | C8: 45467 | D8: Carousel | E8: #AppleMusic | F8: #AppleLifestyle | G8: 7713 | H8: 575 | I8: 417 | J8: 336 | K8: 61660 | L8: 66017 | M8: iPhone 16 Launch | N8: =(Posts[[#This Row],[Likes]]+Posts[[#This Row],[Shares]]+Posts[[#This Row],[Comments]])/Posts[[#This Row],[Impressions]] -> 0.13185998 | O8: #AppleLifestyle | P8: 336 | Q8: 66017 | R8: =(Posts[[#This Row],[Likes]]+Posts[[#This Row],[Shares]]+Posts[[#This Row],[Comments]])/Posts[[#This Row],[Impressions]] -> 0.13185998
A9: A8 | B9: Instagram | C9: 45486 | D9: Video | E9: #AppleWatch | F9: #Health | G9: 18639 | H9: 1360 | I9: 898 | J9: 2011 | K9: 42841 | L9: 247779 | M9: iPhone 16 Launch | N9: =(Posts[[#This Row],[Likes]]+Posts[[#This Row],[Shares]]+Posts[[#This Row],[Comments]])/Posts[[#This Row],[Impressions]] -> 0.084337252 | O9: #Health | P9: 2011 | Q9: 247779 | R9: =(Posts[[#This Row],[Likes]]+Posts[[#This Row],[Shares]]+Posts[[#This Row],[Comments]])/Posts[[#This Row],[Impressions]] -> 0.084337252
A10: A9 | B10: YouTube | C10: 45534 | D10: Carousel | E10: #MacBookAirM3 | F10: #AppleInnovation | G10: 6804 | H10: 787 | I10: 970 | J10: 1095 | K10: 56343 | L10: 164677 | M10: Apple Watch Ultra 2 Launch | N10: =(Posts[[#This Row],[Likes]]+Posts[[#This Row],[Shares]]+Posts[[#This Row],[Comments]])/Posts[[#This Row],[Impressions]] -> 0.051986616 | O10: #AppleInnovation | P10: 1095 | Q10: 164677 | R10: =(Posts[[#This Row],[Likes]]+Posts[[#This Row],[Shares]]+Posts[[#This Row],[Comments]])/Posts[[#This Row],[Impressions]] -> 0.051986616
A11: A10 | B11: Twitter | C11: 45727 | D11: Video | E11: #iPhone16Launch | F11: #AppleEvent | G11: 20222 | H11: 712 | I11: 604 | J11: 1272 | K11: 71598 | L11: 216422 | M11: Sustainability Awareness Drive | N11: =(Posts[[#This Row],[Likes]]+Posts[[#This Row],[Shares]]+Posts[[#This Row],[Comments]])/Posts[[#This Row],[Impressions]] -> 0.099518533 | O11: #AppleEvent | P11: 1272 | Q11: 216422 | R11: =(Posts[[#This Row],[Likes]]+Posts[[#This Row],[Shares]]+Posts[[#This Row],[Comments]])/Posts[[#This Row],[Impressions]] -> 0.099518533
A12: A11 | B12: YouTube | C12: 45690 | D12: Carousel | E12: #AppleEvent | F12: #iPadPro | G12: 12136 | H12: 1117 | I12: 834 | J12: 892 | K12: 24675 | L12: 183273 | M12: Sustainability Awareness Drive | N12: =(Posts[[#This Row],[Likes]]+Posts[[#This Row],[Shares]]+Posts[[#This Row],[Comments]])/Posts[[#This Row],[Impressions]] -> 0.076863477 | O12: #iPadPro | P12: 892 | Q12: 183273 | R12: =(Posts[[#This Row],[Likes]]+Posts[[#This Row],[Shares]]+Posts[[#This Row],[Comments]])/Posts[[#This Row],[Impressions]] -> 0.076863477
A13: A12 | B13: YouTube | C13: 45494 | D13: Tweet | E13: #MacBookAirM3 | F13: #AppleInnovation | G13: 2009 | H13: 1072 | I13: 550 | J13: 1437 | K13: 22982 | L13: 69426 | M13: iPhone 16 Launch | N13: =(Posts[[#This Row],[Likes]]+Posts[[#This Row],[Shares]]+Posts[[#This Row],[Comments]])/Posts[[#This Row],[Impressions]] -> 0.052300291 | O13: #AppleInnovation | P13: 1437 | Q13: 69426 | R13: =(Posts[[#This Row],[Likes]]+Posts[[#This Row],[Shares]]+Posts[[#This Row],[Comments]])/Posts[[#This Row],[Impressions]] -> 0.052300291
... A301: A300 | B301: LinkedIn | C301: 45926 | D301: Video | E301: #iPhone16Launch | F301: #AppleEvent | G301: 21216 | H301: 226 | I301: 187 | J301: 1573 | K301: 62688 | L301: 111031 | M301: Apple Event September 2025 | N301: =(Posts[[#This Row],[Likes]]+Posts[[#This Row],[Shares]]+Posts[[#This Row],[Comments]])/Posts[[#This Row],[Impressions]] -> 0.19480145 | O301: #AppleEvent | P301: 1573 | Q301: 111031 | R301: =(Posts[[#This Row],[Likes]]+Posts[[#This Row],[Shares]]+Posts[[#This Row],[Comments]])/Posts[[#This Row],[Impressions]] -> 0.19480145
O302: #AppleWatchUltra2 | P302: 2675 | Q302: 202932 | R302: 0.13041807
O303: #MacBookAirM3 | P303: 1574 | Q303: 71585 | R303: 0.088356499
O304: #AppleDesign | P304: 1499 | Q304: 193087 | R304: 0.11093963
O305: #AppleEvent | P305: 1925 | Q305: 248611 | R305: 0.020023249
O306: #AppleWatchUltra2 | P306: 1213 | Q306: 83585 | R306: 0.2687085
O307: #ShotOniPhone | P307: 753 | Q307: 66958 | R307: 0.23849279
O308: #AppleMusic | P308: 336 | Q308: 66017 | R308: 0.13185998
O309: #AppleWatch | P309: 2011 | Q309: 247779 | R309: 0.084337252
O310: #MacBookAirM3 | P310: 1095 | Q310: 164677 | R310: 0.051986616
O311: #iPhone16Launch | P311: 1272 | Q311: 216422 | R311: 0.099518533
O312: #AppleEvent | P312: 892 | Q312: 183273 | R312: 0.076863477
O313: #MacBookAirM3 | P313: 1437 | Q313: 69426 | R313: 0.052300291
... O601: #iPhone16Launch | P601: 1573 | Q601: 111031 | R601: 0.19480145

Sheet Engagement Summary
A1: Week_Start_Date | B1: Platform | C1: New_Followers | D1: Unfollows | E1: Total_Followers | F1: Engagement_Rate | G1: Ad_Spend | H1: Followers Growth Rate | I1: Follower Gain | J1: Column1
A2: 45446 | B2: Instagram | C2: 4138 | D2: 361 | E2: 103777 | F2: 56.64 | G2: 23944 | H2: =(Engagement_Summary[[#This Row],[New_Followers]]-Engagement_Summary[[#This Row],[Unfollows]])/Engagement_Summary[[#This Row],[Total_Followers]] -> 0.036395348 | I2: =Engagement_Summary[[#This Row],[New_Followers]]-Engagement_Summary[[#This Row],[Unfollows]] -> 3777 | J2: #N/A
A3: 45446 | B3: Twitter | C3: 8693 | D3: 1261 | E3: 111209 | F3: 69.48 | G3: 29873 | H3: =(Engagement_Summary[[#This Row],[New_Followers]]-Engagement_Summary[[#This Row],[Unfollows]])/Engagement_Summary[[#This Row],[Total_Followers]] -> 0.066829124 | I3: =Engagement_Summary[[#This Row],[New_Followers]]-Engagement_Summary[[#This Row],[Unfollows]] -> 7432 | J3: #N/A
A4: 45446 | B4: YouTube | C4: 9264 | D4: 1141 | E4: 119332 | F4: 92.31 | G4: 50372 | H4: =(Engagement_Summary[[#This Row],[New_Followers]]-Engagement_Summary[[#This Row],[Unfollows]])/Engagement_Summary[[#This Row],[Total_Followers]] -> 0.068070593 | I4: =Engagement_Summary[[#This Row],[New_Followers]]-Engagement_Summary[[#This Row],[Unfollows]] -> 8123 | J4: #N/A
A5: 45446 | B5: YouTube | C5: 8842 | D5: 971 | E5: 127203 | F5: 16.35 | G5: 33928 | H5: =(Engagement_Summary[[#This Row],[New_Followers]]-Engagement_Summary[[#This Row],[Unfollows]])/Engagement_Summary[[#This Row],[Total_Followers]] -> 0.061877471 | I5: =Engagement_Summary[[#This Row],[New_Followers]]-Engagement_Summary[[#This Row],[Unfollows]] -> 7871 | J5: #N/A
A6: 45453 | B6: Instagram | C6: 7721 | D6: 506 | E6: 134418 | F6: 35.58 | G6: 25379 | H6: =(Engagement_Summary[[#This Row],[New_Followers]]-Engagement_Summary[[#This Row],[Unfollows]])/Engagement_Summary[[#This Row],[Total_Followers]] -> 0.053675847 | I6: =Engagement_Summary[[#This Row],[New_Followers]]-Engagement_Summary[[#This Row],[Unfollows]] -> 7215 | J6: #N/A
A7: 45453 | B7: YouTube | C7: 8002 | D7: 524 | E7: 141896 | F7: 52.06 | G7: 46751 | H7: =(Engagement_Summary[[#This Row],[New_Followers]]-Engagement_Summary[[#This Row],[Unfollows]])/Engagement_Summary[[#This Row],[Total_Followers]] -> 0.052700569 | I7: =Engagement_Summary[[#This Row],[New_Followers]]-Engagement_Summary[[#This Row],[Unfollows]] -> 7478 | J7: #N/A
A8: 45453 | B8: Twitter | C8: 5225 | D8: 291 | E8: 146830 | F8: 19.55 | G8: 44546 | H8: =(Engagement_Summary[[#This Row],[New_Followers]]-Engagement_Summary[[#This Row],[Unfollows]])/Engagement_Summary[[#This Row],[Total_Followers]] -> 0.033603487 | I8: =Engagement_Summary[[#This Row],[New_Followers]]-Engagement_Summary[[#This Row],[Unfollows]] -> 4934 | J8: =AVERAGE(I3:I9) -> 6641.1429
A9: 45453 | B9: Twitter | C9: 3978 | D9: 543 | E9: 150265 | F9: 49.16 | G9: 34286 | H9: =(Engagement_Summary[[#This Row],[New_Followers]]-Engagement_Summary[[#This Row],[Unfollows]])/Engagement_Summary[[#This Row],[Total_Followers]] -> 0.022859615 | I9: =Engagement_Summary[[#This Row],[New_Followers]]-Engagement_Summary[[#This Row],[Unfollows]] -> 3435 | J9: =AVERAGE(I4:I10) -> 6644
A10: 45460 | B10: Instagram | C10: 8373 | D10: 921 | E10: 157717 | F10: 12.23 | G10: 15110 | H10: =(Engagement_Summary[[#This Row],[New_Followers]]-Engagement_Summary[[#This Row],[Unfollows]])/Engagement_Summary[[#This Row],[Total_Followers]] -> 0.047249187 | I10: =Engagement_Summary[[#This Row],[New_Followers]]-Engagement_Summary[[#This Row],[Unfollows]] -> 7452 | J10: =AVERAGE(I5:I11) -> 6351.1429
A11: 45460 | B11: Twitter | C11: 6907 | D11: 834 | E11: 163790 | F11: 54.16 | G11: 22087 | H11: =(Engagement_Summary[[#This Row],[New_Followers]]-Engagement_Summary[[#This Row],[Unfollows]])/Engagement_Summary[[#This Row],[Total_Followers]] -> 0.037077966 | I11: =Engagement_Summary[[#This Row],[New_Followers]]-Engagement_Summary[[#This Row],[Unfollows]] -> 6073 | J11: =AVERAGE(I6:I12) -> 6187.8571
A12: 45460 | B12: LinkedIn | C12: 7097 | D12: 369 | E12: 170518 | F12: 9.25 | G12: 33762 | H12: =(Engagement_Summary[[#This Row],[New_Followers]]-Engagement_Summary[[#This Row],[Unfollows]])/Engagement_Summary[[#This Row],[Total_Followers]] -> 0.039456245 | I12: =Engagement_Summary[[#This Row],[New_Followers]]-Engagement_Summary[[#This Row],[Unfollows]] -> 6728 | J12: =AVERAGE(I7:I13) -> 5968.2857
A13: 45460 | B13: Instagram | C13: 6656 | D13: 978 | E13: 176196 | F13: 60.43 | G13: 27081 | H13: =(Engagement_Summary[[#This Row],[New_Followers]]-Engagement_Summary[[#This Row],[Unfollows]])/Engagement_Summary[[#This Row],[Total_Followers]] -> 0.032225476 | I13: =Engagement_Summary[[#This Row],[New_Followers]]-Engagement_Summary[[#This Row],[Unfollows]] -> 5678 | J13: =AVERAGE(I8:I14) -> 6136.2857
A14: 45467 | B14: Twitter | C14: 9984 | D14: 1330 | E14: 184850 | F14: 57.52 | G14: 44947 | H14: =(Engagement_Summary[[#This Row],[New_Followers]]-Engagement_Summary[[#This Row],[Unfollows]])/Engagement_Summary[[#This Row],[Total_Followers]] -> 0.046816338 | I14: =Engagement_Summary[[#This Row],[New_Followers]]-Engagement_Summary[[#This Row],[Unfollows]] -> 8654 | J14: =AVERAGE(I9:I15) -> 6129.2857
A15: 45467 | B15: Instagram | C15: 5259 | D15: 374 | E15: 189735 | F15: 14.83 | G15: 19596 | H15: =(Engagement_Summary[[#This Row],[New_Followers]]-Engagement_Summary[[#This Row],[Unfollows]])/Engagement_Summary[[#This Row],[Total_Followers]] -> 0.025746436 | I15: =Engagement_Summary[[#This Row],[New_Followers]]-Engagement_Summary[[#This Row],[Unfollows]] -> 4885 | J15: =AVERAGE(I10:I16) -> 6874.7143
A16: 45467 | B16: YouTube | C16: 9286 | D16: 633 | E16: 198388 | F16: 5.43 | G16: 48019 | H16: =(Engagement_Summary[[#This Row],[New_Followers]]-Engagement_Summary[[#This Row],[Unfollows]])/Engagement_Summary[[#This Row],[Total_Followers]] -> 0.043616549 | I16: =Engagement_Summary[[#This Row],[New_Followers]]-Engagement_Summary[[#This Row],[Unfollows]] -> 8653 | J16: =AVERAGE(I11:I17) -> 6728.7143
A17: 45467 | B17: Twitter | C17: 6901 | D17: 471 | E17: 204818 | F17: 60.83 | G17: 52003 | H17: =(Engagement_Summary[[#This Row],[New_Followers]]-Engagement_Summary[[#This Row],[Unfollows]])/Engagement_Summary[[#This Row],[Total_Followers]] -> 0.031393725 | I17: =Engagement_Summary[[#This Row],[New_Followers]]-Engagement_Summary[[#This Row],[Unfollows]] -> 6430 | J17: =AVERAGE(I12:I18) -> 6638.5714
A18: 45474 | B18: LinkedIn | C18: 5917 | D18: 475 | E18: 210260 | F18: 17.89 | G18: 28313 | H18: =(Engagement_Summary[[#This Row],[New_Followers]]-Engagement_Summary[[#This Row],[Unfollows]])/Engagement_Summary[[#This Row],[Total_Followers]] -> 0.025882241 | I18: =Engagement_Summary[[#This Row],[New_Followers]]-Engagement_Summary[[#This Row],[Unfollows]] -> 5442 | J18: =AVERAGE(I13:I19) -> 6886.4286
A19: 45474 | B19: Twitter | C19: 9429 | D19: 966 | E19: 218723 | F19: 7.69 | G19: 57639 | H19: =(Engagement_Summary[[#This Row],[New_Followers]]-Engagement_Summary[[#This Row],[Unfollows]])/Engagement_Summary[[#This Row],[Total_Followers]] -> 0.038692776 | I19: =Engagement_Summary[[#This Row],[New_Followers]]-Engagement_Summary[[#This Row],[Unfollows]] -> 8463 | J19: =AVERAGE(I14:I20) -> 6532.7143
... A200: 45789 | B200: LinkedIn | C200: 1301 | D200: 180 | E200: 1178962 | F200: 5.23 | G200: 44521 | H200: =(Engagement_Summary[[#This Row],[New_Followers]]-Engagement_Summary[[#This Row],[Unfollows]])/Engagement_Summary[[#This Row],[Total_Followers]] -> 0.00095083641 | I200: =Engagement_Summary[[#This Row],[New_Followers]]-Engagement_Summary[[#This Row],[Unfollows]] -> 1121 | J200: =AVERAGE(I195:I201) -> 4803.2857
A201: 45789 | B201: Twitter | C201: 8527 | D201: 1091 | E201: 1186398 | F201: 1.68 | G201: 41703 | H201: =(Engagement_Summary[[#This Row],[New_Followers]]-Engagement_Summary[[#This Row],[Unfollows]])/Engagement_Summary[[#This Row],[Total_Followers]] -> 0.0062677112 | I201: =Engagement_Summary[[#This Row],[New_Followers]]-Engagement_Summary[[#This Row],[Unfollows]] -> 7436

Sheet Campaign Metadata
A1: Campaign_Name | B1: Start_Date | C1: End_Date | D1: Objective | E1: Ad_Spend | F1: Impressions | G1: Engagement_Uplift | H1: TOTAL FOLOWER GAINS | I1: TOTAL FOLLOWERS GAINS | K1: WEEKLY FOLLOWER GAINS
A2: iPhone 16 Launch | B2: 45458 | C2: 45488 | D2: Product Launch | E2: 85000 | F2: 950000 | G2: 0.45 | H2: ='Campaign Metadata'!L8+'Campaign Metadata'!L9+'Campaign Metadata'!L11+'Campaign Metadata'!L12+'Campaign Metadata'!L13 -> 106800 | I2: =SUMIFS('Engagement Summary'!I:I,'Engagement Summary'!A:A,">="&B2,'Engagement Summary'!A:A,"<="&C2) -> 106800
A3: MacBook Air M3 Campaign | B3: 45566 | C3: 45596 | D3: Product Promotion | E3: 60000 | F3: 780000 | G3: 0.38 | H3: =SUM('Campaign Metadata'!L19:L22) -> 99093 | I3: =SUMIFS('Engagement Summary'!I:I,'Engagement Summary'!A:A,">="&B3,'Engagement Summary'!A:A,"<="&C3) -> 99093 | K3: Row Labels | L3: Sum of Follower Gains
A4: Apple Watch Ultra 2 Launch | B4: 45651 | C4: 45667 | D4: Health & Fitness Awareness | E4: 55000 | F4: 700000 | G4: 0.41 | H4: =SUM('Campaign Metadata'!L29:L32) -> 50927 | I4: =SUMIFS('Engagement Summary'!I:I,'Engagement Summary'!A:A,">="&B4,'Engagement Summary'!A:A,"<="&C4) -> 50927 | K4: 2024
A5: Sustainability Awareness Drive | B5: 45717 | C5: 45747 | D5: Sustainability Branding | E5: 40000 | F5: 550000 | G5: 0.32 | H5: =SUM('Campaign Metadata'!L38:L42) -> 107259 | I5: =SUMIFS('Engagement Summary'!I:I,'Engagement Summary'!A:A,">="&B5,'Engagement Summary'!A:A,"<="&C5) -> 107259 | K5: Jun
A6: Apple Event September 2025 | B6: 45901 | C6: 45930 | D6: Brand Engagement | E6: 75000 | F6: 880000 | G6: 0.47 | H6: 0 | I6: =SUMIFS('Engagement Summary'!I:I,'Engagement Summary'!A:A,">="&B6,'Engagement Summary'!A:A,"<="&C6) -> 0 | K6: 45446 | L6: 27203
K7: 45453 | L7: 23062
K8: 45460 | L8: 25931
K9: 45467 | L9: 28622
K10: Jul
K11: 45474 | L11: 19833
K12: 45481 | L12: 18529
K13: 45488 | L13: 13885
K14: 45495 | L14: 32218
K15: 45502 | L15: 17021
K16: Aug | L16: 84848
K17: Sep | L17: 99241
K18: Oct
K19: 45572 | L19: 17577
K20: 45579 | L20: 23371
K21: 45586 | L21: 30891
K22: 45593 | L22: 27254
K23: Nov | L23: 86299
K24: Dec
K25: 45628 | L25: 18330
K26: 45635 | L26: 15842
K27: 45642 | L27: 19604
K28: 45649 | L28: 19183
K29: 45656 | L29: 23870
K30: 2025
K31: Jan
K32: 45663 | L32: 27057
K33: 45670 | L33: 18737
K34: 45677 | L34: 27809
K35: 45684 | L35: 22692
K36: Feb | L36: 90480
K37: Mar
K38: 45719 | L38: 20389
K39: 45726 | L39: 17807
K40: 45733 | L40: 28020
...

Sheet TASK 1

Sheet TASK 2
B2: AVERAGE ENGAGEMENT RATE PER PLATFORM | E2: TOTAL COMMENTS,SHARES & LIKES BY CONTENT TYPE & PLATFORM | J2: AVERAGE CLICKS PER POST BY HASHTAGS
B4: Platform | C4: Average of Engagement Rate | E4: PLATFORM & CONTENT TYPE | F4: Sum of Comments | G4: Sum of Shares | H4: Sum of Likes | J4: HASHTAGS | K4: Average of CLICKS
B5: YouTube | C5: 0.11218828 | E5: YouTube | F5: 42629 | G5: 67460 | H5: 948258 | J5: #AppleDesign | K5: 1592.72
B6: Twitter | C6: 0.13887773 | E6: Carousel | F6: 13714 | G6: 24668 | H6: 279732 | J6: #AppleEarth | K6: 1459.3077
B7: LinkedIn | C7: 0.12413747 | E7: Image | F7: 8277 | G7: 10604 | H7: 195079 | J7: #AppleEvent | K7: 1639.225
B8: Instagram | C8: 0.11777136 | E8: Tweet | F8: 8101 | G8: 14136 | H8: 187129 | J8: #AppleInnovation | K8: 1680.3571
B9: Grand Total | C9: 0.12284133 | E9: Video | F9: 12537 | G9: 18052 | H9: 286318 | J9: #AppleLifestyle | K9: 1463.2941
E10: Twitter | F10: 39273 | G10: 59661 | H10: 1037623 | J10: #AppleMusic | K10: 1463.2941
E11: Carousel | F11: 14381 | G11: 21298 | H11: 394886 | J11: #AppleWatch | K11: 1711.5135
E12: Image | F12: 6092 | G12: 7832 | H12: 148676 | J12: #AppleWatchUltra2 | K12: 1674.96
B13: TOP 10 APPLE POST WITH HIGHEST ENAGEMENT | E13: Tweet | F13: 9160 | G13: 15862 | H13: 249305 | J13: #Health | K13: 1711.5135
E14: Video | F14: 9640 | G14: 14669 | H14: 244756 | J14: #HealthTech | K14: 1674.96
B15: POST ID | C15: Sum of Engagement Rate | E15: LinkedIn | F15: 49700 | G15: 70960 | H15: 1134366 | J15: #Innovation | K15: 1592.72
B16: A82 | C16: 0.49054106 | E16: Carousel | F16: 12611 | G16: 18856 | H16: 246297 | J16: #iPadPro | K16: 1477.2632
B17: A201 | C17: 0.48803915 | E17: Image | F17: 14305 | G17: 19905 | H17: 329722 | J17: #iPhone16 | K17: 1579.4375
B18: A121 | C18: 0.45492807 | E18: Tweet | F18: 11014 | G18: 17963 | H18: 279588 | J18: #iPhone16Launch | K18: 1811.3103
B19: A127 | C19: 0.41655672 | E19: Video | F19: 11770 | G19: 14236 | H19: 278759 | J19: #iPhonePhotography | K19: 1706.76
B20: A13 | C20: 0.40382152 | E20: Instagram | F20: 40786 | G20: 63205 | H20: 947196 | J20: #MacBookAirM3 | K20: 1680.3571
B21: A123 | C21: 0.39401344 | E21: Carousel | F21: 13676 | G21: 16508 | H21: 278757 | J21: #MacBookProM3 | K21: 1289.4118
B22: A287 | C22: 0.367641 | E22: Image | F22: 10389 | G22: 18753 | H22: 218031 | J22: #ShotOniPhone | K22: 1662.3415
B23: A226 | C23: 0.35412345 | E23: Tweet | F23: 9295 | G23: 14750 | H23: 206053 | J23: #Sustainability | K23: 1459.3077
B24: A231 | C24: 0.33944448 | E24: Video | F24: 7426 | G24: 13194 | H24: 244355 | J24: Grand Total | K24: 1616.5838
B25: A185 | C25: 0.33811899 | E25: Grand Total | F25: 172388 | G25: 261286 | H25: 4067443
B26: Grand Total | C26: 4.0472279
E28: TOP PERFORMING HASHTAGS | H28: TOP 5 PERFORMING HASHTAGS
E30: HASHTAGS | F30: Average of Impressions
E31: #AppleDesign | F31: 152305.92
E32: #AppleEarth | F32: 127317.77
E33: #AppleEvent | F33: 155223.7
E34: #AppleInnovation | F34: 152129.11
E35: #AppleLifestyle | F35: 142767
E36: #AppleMusic | F36: 142767
E37: #AppleWatch | F37: 156354.51
E38: #AppleWatchUltra2 | F38: 126552.08
E39: #Health | F39: 156354.51
E40: #HealthTech | F40: 126552.08
E41: #Innovation | F41: 152305.92
E42: #iPadPro | F42: 155947.84
... E50: Grand Total | F50: 148225.02

Sheet TASK 3
B2: AVERAGE EAGAGEMENT RATE OF PLATFORMS BY APPLE CAMPAIGNS | I2: AVERAGE FOLLOWERS GROWTH RATE OF PLATFORMS
B4: Average of Engagement Rate | C4: Column Labels | I4: PLATFORM | J4: Average of Followers Growth Rate
B5: CAMPAIGNS | C5: Instagram | D5: LinkedIn | E5: Twitter | F5: YouTube | G5: Grand Total | I5: Instagram | J5: 0.012030686
B6: Apple Event September 2025 | C6: 0.13193785 | D6: 0.11210848 | E6: 0.14856462 | F6: 0.10380076 | G6: 0.12042553 | I6: LinkedIn | J6: 0.0094286448
B7: Apple Watch Ultra 2 Launch | C7: 0.13679934 | D7: 0.1441191 | E7: 0.1430731 | F7: 0.11973748 | G7: 0.1368382 | I7: Twitter | J7: 0.013764362
B8: iPhone 16 Launch | C8: 0.096402731 | D8: 0.12843165 | E8: 0.1352676 | F8: 0.11995588 | G8: 0.12196385 | I8: YouTube | J8: 0.014194034
B9: MacBook Air M3 Campaign | C9: 0.09560217 | D9: 0.12478605 | E9: 0.14429365 | F9: 0.11559353 | G9: 0.11861255 | I9: Grand Total | J9: 0.012218035
B10: Sustainability Awareness Drive | C10: 0.11414924 | D10: 0.1020845 | E10: 0.12718694 | F10: 0.10497763 | G10: 0.11314309
B11: Grand Total | C11: 0.11777136 | D11: 0.12413747 | E11: 0.13887773 | F11: 0.11218828 | G11: 0.12284133
B14: ENAGEMENT VS AD_SPEND BY PLATFORMS | F14: FOLLOWERS GROWTH RATE VS AD_ SPEND BY PLATFORMS
B16: PLATFORM | C16: Average of Engagement_Rate | D16: Average of Ad_Spend | F16: PLATFORM | G16: Average of Followers Growth Rate | H16: Average of Ad_Spend
B17: Instagram | C17: 15.559412 | D17: 34821.235 | F17: Instagram | G17: 0.012030686 | H17: 34821.235
B18: LinkedIn | C18: 14.067636 | D18: 36191.327 | F18: LinkedIn | G18: 0.0094286448 | H18: 36191.327
B19: Twitter | C19: 17.480943 | D19: 35360.057 | F19: Twitter | G19: 0.013764362 | H19: 35360.057
B20: YouTube | C20: 17.599512 | D20: 31374.902 | F20: YouTube | G20: 0.014194034 | H20: 31374.902
B21: Grand Total | C21: 16.0766 | D21: 34634.3 | F21: Grand Total | G21: 0.012218035 | H21: 34634.3
B45: COMBO CHART FOR ENAGEMENT RATE VS AD_SPEND | F45: COMBO CHART FOR FOLLOWERS GROWTH RATE VS AD_SPEND

Sheet TASK 4
B2: MOST FREQUENTLY USED APPLE HASHTAGS | E2: AVERAGE PERFORMANCE OF EACH HASHTAGS | H2: CONTENT ENGAGEMENT CONTRIBUTION
B4: HASHTAG | C4: Count of HASTAGS | E4: HASHTAG | F4: Average of Engagement Rate | H4: CONTENT TYPE | I4: Average of Engagement Rate
B5: #AppleEvent | C5: 80 | E5: #AppleDesign | F5: 0.11135741 | H5: Video | I5: 0.13929223
B6: #ShotOniPhone | C6: 41 | E6: #AppleEarth | F6: 0.12019462 | H6: Tweet | I6: 0.11357605
B7: #AppleWatch | C7: 37 | E7: #AppleEvent | F7: 0.1185215 | H7: Image | I7: 0.11546429
B8: #Health | C8: 37 | E8: #AppleInnovation | F8: 0.1178941 | H8: Carousel | I8: 0.12254707
B9: #AppleMusic | C9: 34 | E9: #AppleLifestyle | F9: 0.13494947 | H9: Grand Total | I9: 0.12284133
B10: #AppleLifestyle | C10: 34 | E10: #AppleMusic | F10: 0.13494947
B11: #iPhone16 | C11: 32 | E11: #AppleWatch | F11: 0.11399722
B12: #iPhone16Launch | C12: 29 | E12: #AppleWatchUltra2 | F12: 0.14380411
B13: #MacBookAirM3 | C13: 28 | E13: #Health | F13: 0.11399722
B14: #AppleInnovation | C14: 28 | E14: #HealthTech | F14: 0.14380411
B15: #AppleWatchUltra2 | C15: 25 | E15: #Innovation | F15: 0.11135741
B16: #iPhonePhotography | C16: 25 | E16: #iPadPro | F16: 0.11195695
B17: #AppleDesign | C17: 25 | E17: #iPhone16 | F17: 0.12600407
B18: #Innovation | C18: 25 | E18: #iPhone16Launch | F18: 0.1145658
B19: #HealthTech | C19: 25 | E19: #iPhonePhotography | F19: 0.12026677
B20: #iPadPro | C20: 19 | E20: #MacBookAirM3 | F20: 0.1178941
B21: #MacBookProM3 | C21: 17 | E21: #MacBookProM3 | F21: 0.10955527
... B24: Grand Total | C24: 567 | E24: Grand Total | F24: 0.12238019
B26: CONTENT PERFORMANCE FOR EACH CAMPAIGN | E26: COMPARATIVE ANALYSIS OF CONTENT ENGAGEMENT BY CAMPAIGN
B28: Row Labels | C28: Average of Engagement Rate
B29: Video | C29: 0.13929223
B30: Sustainability Awareness Drive | C30: 0.14671342
B31: MacBook Air M3 Campaign | C31: 0.098301267
B32: iPhone 16 Launch | C32: 0.12164066
B33: Apple Watch Ultra 2 Launch | C33: 0.16660506
B34: Apple Event September 2025 | C34: 0.13265746
B35: Tweet | C35: 0.11357605
B36: Sustainability Awareness Drive | C36: 0.10373784
B37: MacBook Air M3 Campaign | C37: 0.10776982
B38: iPhone 16 Launch | C38: 0.11429578
B39: Apple Watch Ultra 2 Launch | C39: 0.1199968
B40: Apple Event September 2025 | C40: 0.11931131
... B53: Grand Total | C53: 0.12284133

Sheet TASK 5
A1: Campaign_Name | B1: Start_Date | C1: End_Date | D1: Objective | E1: Ad_Spend | F1: Impressions | G1: Engagement_Uplift | H1: BEFORE UPLIFT | I1: DURING UPLIFT | J1: ROI | K1: ROI*1000000 | L1: TOTAL FOLOWER GAINS | M1: TOTAL FOLLOWERS GAINS | O1: WEEKLY FOLLOWER GAINS
A2: iPhone 16 Launch | B2: 45458 | C2: 45488 | D2: Product Launch | E2: 85000 | F2: 950000 | G2: 0.45 | H2: 1 | I2: =Campaign_Metadata5[[#This Row],[BEFORE UPLIFT]]+Campaign_Metadata5[[#This Row],[Engagement_Uplift]] -> 1.45 | J2: =Campaign_Metadata5[[#This Row],[Engagement_Uplift]]/Campaign_Metadata5[[#This Row],[Ad_Spend]] -> 5.2941176e-06 | K2: =Campaign_Metadata5[[#This Row],[ROI]]*1000000 -> 5.2941176 | L2: 106800 | M2: 106800
A3: MacBook Air M3 Campaign | B3: 45566 | C3: 45596 | D3: Product Promotion | E3: 60000 | F3: 780000 | G3: 0.38 | H3: 1 | I3: =Campaign_Metadata5[[#This Row],[BEFORE UPLIFT]]+Campaign_Metadata5[[#This Row],[Engagement_Uplift]] -> 1.38 | J3: =Campaign_Metadata5[[#This Row],[Engagement_Uplift]]/Campaign_Metadata5[[#This Row],[Ad_Spend]] -> 6.3333333e-06 | K3: =Campaign_Metadata5[[#This Row],[ROI]]*1000000 -> 6.3333333 | L3: 99093 | M3: 99093 | O3: WEEK_START_DATE | P3: Sum of Follower Gains
A4: Apple Watch Ultra 2 Launch | B4: 45651 | C4: 45667 | D4: Health & Fitness Awareness | E4: 55000 | F4: 700000 | G4: 0.41 | H4: 1 | I4: =Campaign_Metadata5[[#This Row],[BEFORE UPLIFT]]+Campaign_Metadata5[[#This Row],[Engagement_Uplift]] -> 1.41 | J4: =Campaign_Metadata5[[#This Row],[Engagement_Uplift]]/Campaign_Metadata5[[#This Row],[Ad_Spend]] -> 7.4545455e-06 | K4: =Campaign_Metadata5[[#This Row],[ROI]]*1000000 -> 7.4545455 | L4: 50927 | M4: 50927 | O4: 2024
A5: Sustainability Awareness Drive | B5: 45717 | C5: 45747 | D5: Sustainability Branding | E5: 40000 | F5: 550000 | G5: 0.32 | H5: 1 | I5: =Campaign_Metadata5[[#This Row],[BEFORE UPLIFT]]+Campaign_Metadata5[[#This Row],[Engagement_Uplift]] -> 1.32 | J5: =Campaign_Metadata5[[#This Row],[Engagement_Uplift]]/Campaign_Metadata5[[#This Row],[Ad_Spend]] -> 8e-06 | K5: =Campaign_Metadata5[[#This Row],[ROI]]*1000000 -> 8 | L5: 107259 | M5: 107259 | O5: Jun
A6: Apple Event September 2025 | B6: 45901 | C6: 45930 | D6: Brand Engagement | E6: 75000 | F6: 880000 | G6: 0.47 | H6: 1 | I6: =Campaign_Metadata5[[#This Row],[BEFORE UPLIFT]]+Campaign_Metadata5[[#This Row],[Engagement_Uplift]] -> 1.47 | J6: =Campaign_Metadata5[[#This Row],[Engagement_Uplift]]/Campaign_Metadata5[[#This Row],[Ad_Spend]] -> 6.2666667e-06 | K6: =Campaign_Metadata5[[#This Row],[ROI]]*1000000 -> 6.2666667 | L6: 0 | M6: 0 | O6: 45446 | P6: 27203
O7: 45453 | P7: 23062
F8: ENGAGEMENT UPLIFT DURING VS BEFORE CAMPAIGNS | K8: CAMPAIGN-WISE ROI COMPARISON | O8: 45460 | P8: 25931
A9: TOTAL IMPRESSIONS, LIKES & CLICKS PER CAMPAIGN | O9: 45467 | P9: 28622
O10: Jul
A11: Row Labels | B11: Sum of Impressions | C11: Sum of Likes | D11: Sum of Clicks | O11: 45474 | P11: 19833
A12: Apple Event September 2025 | B12: 10331022 | C12: 957050 | D12: 114854 | O12: 45481 | P12: 18529
A13: Apple Watch Ultra 2 Launch | B13: 9407749 | C13: 888529 | D13: 106775 | O13: 45488 | P13: 13885
A14: iPhone 16 Launch | B14: 8901334 | C14: 843431 | D14: 96543 | O14: 45495 | P14: 32218
A15: MacBook Air M3 Campaign | B15: 6698763 | C15: 585970 | D15: 74667 | O15: 45502 | P15: 17021
A16: Sustainability Awareness Drive | B16: 9222999 | C16: 792463 | D16: 89166 | O16: Aug | P16: 84848
A17: Grand Total | B17: 44561867 | C17: 4067443 | D17: 482005 | O17: Sep | P17: 99241
O18: Oct | P18: 99093
A19: AVERAGE IMPRESSION, LIKES & CLICKS PER CAMPAIGN | O19: Nov | P19: 86299
O20: Dec
A21: Row Labels | B21: Average of Impressions | C21: Average of Likes | D21: Average of Clicks | O21: 45628 | P21: 18330
A22: Apple Event September 2025 | B22: 149724.96 | C22: 13870.29 | D22: 1664.5507 | O22: 45635 | P22: 15842
A23: Apple Watch Ultra 2 Launch | B23: 136344.19 | C23: 12877.232 | D23: 1547.4638 | O23: 45642 | P23: 19604
A24: iPhone 16 Launch | B24: 150870.07 | C24: 14295.441 | D24: 1636.322 | O24: 45649 | P24: 19183
A25: MacBook Air M3 Campaign | B25: 145625.28 | C25: 12738.478 | D25: 1623.1957 | O25: 45656 | P25: 23870
A26: Sustainability Awareness Drive | B26: 161807 | C26: 13902.86 | D26: 1564.3158 | J26: CAMPAIGN-WISE FOLLOWER GROWTH | O26: 2025
A27: Grand Total | B27: 148539.56 | C27: 13558.143 | D27: 1606.6833 | O27: Jan
O28: 45663 | P28: 27057
O29: 45670 | P29: 18737
O30: 45677 | P30: 27809
O31: 45684 | P31: 22692
O32: Feb | P32: 90480
O33: Mar | P33: 107259
O34: Apr | P34: 85234
O35: May | P35: 34516
O36: Grand Total | P36: 1086398

Sheet TASK 6
N1: Week_Start_Date | O1: (All)
B2: WEEKLY PLATFORM GROWTH ANALYSIS | F2: PLATFORM-WISE GROWTH RATE TRENDS | R2: CORRELATION BETWEEN AD_SPEND Vs FOLLOWER GROWTH RATE
N3: PLATFORM | O3: Sum of Ad_Spend | P3: Sum of Followers Growth Rate
B4: Row Labels | C4: Sum of Followers Growth Rate | N4: Instagram | O4: 0.25637634 | P4: 0.25108988
B5: 2024 | C5: 0.69959398 | N5: LinkedIn | O5: 0.28736296 | P5: 0.21221721
B6: Jun | C6: 0.69959398 | N6: Twitter | O6: 0.27055304 | P6: 0.29853866
B7: 45446 | C7: 0.23317254 | N7: YouTube | O7: 0.18570767 | P7: 0.23815424
B8: Instagram | C8: 0.036395348 | N8: Grand Total | O8: 1 | P8: 1
B9: Twitter | C9: 0.066829124
B10: YouTube | C10: 0.12994806 | N10: CORRELATION MAPPING : AD_SPEN Vs GROWTH
B11: 45453 | C11: 0.16283952
B12: Instagram | C12: 0.053675847 | N12: Platform | O12: Sum of Ad_Spend | P12: Sum of Followers Growth Rate
B13: Twitter | C13: 0.056463102 | N13: Instagram | O13: =GETPIVOTDATA("Sum of Ad_Spend",$N$3,"Platform",N13) -> 0.25637634 | P13: =GETPIVOTDATA("Sum of Followers Growth Rate",$N$3,"Platform",N13) -> 0.25108988
B14: YouTube | C14: 0.052700569 | N14: LinkedIn | O14: =GETPIVOTDATA("Sum of Ad_Spend",$N$3,"Platform",N14) -> 0.28736296 | P14: =GETPIVOTDATA("Sum of Followers Growth Rate",$N$3,"Platform",N14) -> 0.21221721
B15: 45460 | C15: 0.15600887 | N15: Twitter | O15: =GETPIVOTDATA("Sum of Ad_Spend",$N$3,"Platform",N15) -> 0.27055304 | P15: =GETPIVOTDATA("Sum of Followers Growth Rate",$N$3,"Platform",N15) -> 0.29853866
B16: Instagram | C16: 0.079474663 | N16: YouTube | O16: =GETPIVOTDATA("Sum of Ad_Spend",$N$3,"Platform",N16) -> 0.18570767 | P16: =GETPIVOTDATA("Sum of Followers Growth Rate",$N$3,"Platform",N16) -> 0.23815424
B17: LinkedIn | C17: 0.039456245 | N17: Grand Total | O17: =GETPIVOTDATA("Sum of Ad_Spend",$N$3) -> 1 | P17: =GETPIVOTDATA("Sum of Followers Growth Rate",$N$3) -> 1
B18: Twitter | C18: 0.037077966
B19: 45467 | C19: 0.14757305
B20: Instagram | C20: 0.025746436
B21: Twitter | C21: 0.078210063
B22: YouTube | C22: 0.043616549
B23: Grand Total | C23: 0.69959398
B25: TOP 10 WEEK BY FOLLOWER GAIN | E25: TOP 10 PEAK ANALYSIS
B27: Row Labels | C27: Sum of Follower Gain
B28: 45446 | C28: 27203
B29: 45467 | C29: 28622
B30: 45495 | C30: 32218
B31: 45586 | C31: 30891
B32: 45593 | C32: 27254
B33: 45621 | C33: 28625
B34: 45677 | C34: 27809
B35: 45691 | C35: 28533
B36: 45712 | C36: 30446
B37: 45733 | C37: 28020
B38: Grand Total | C38: 289621
J45: FOLLOWER GROWTH & MOVING AVERAGE ANALYSIS

Sheet TASK 7
C6: VIDEO LINK | D6: https://www.loom.com/share/b5ee9c53a33947fbb6c4cdf1e592ea6e
